<?xml version="1.0"?>
<robot name="my_robot">

    <material name="blue">
        <color rgba="0 0 1 1"/>
    </material>

    <material name="gray">
        <color rgba="0.5 0.5 0.5 1"/>
    </material>

    <material name="red">
        <color rgba="1 0 0 1"/>
    </material>


    <link name="base_link">
    <visual>
        <geometry>
            <box size="0.6 0.4 0.2"/>
        </geometry>
        <origin xyz="0 0 0.1" rpy="0 0 0" />
        <material name="blue"/>
    </visual>
    </link>

    <link name="shoulder_link">
    <visual>
        <geometry>
            <cylinder radius="0.1" length="0.3"/>
        </geometry>
        <origin xyz="0 0 0.15" rpy="0 0 0" />
        <material name="gray"/>
    </visual>
    </link>

    <joint name="base_shoulder_joint" type="revolute">
        <parent link="base_link"/>
        <child link="shoulder_link"/>
        <origin xyz="0 0 0.2" rpy="0 0 0"/>
        <axis xyz="0 0 1"/>
        <limit lower="-3.14" upper="3.14" effort="100" velocity="100"/>
    </joint>

    <link name="camera_link">
    <visual>
        <geometry>
            <sphere radius="0.1"/>
        </geometry>
        <origin xyz="0 0 0" rpy="0 0 0" />
        <material name="red"/>
    </visual>
    </link>

    <joint name="shoulder_camera_joint" type="fixed">
        <parent link="shoulder_link"/>
        <child link="camera_link"/>
        <origin xyz="0 0 0.4" rpy="0 0 0"/>
    </joint>

</robot>
