<?xml version="1.0"?>
<robot name="robot_car">

    <material name="blue">
        <color rgba="0 0 1 1"/>
    </material>

    <material name="gray">
        <color rgba="0.5 0.5 0.5 1"/>
    </material>



    <link name="base_link">
    <visual>
        <geometry>
            <box size="0.6 0.4 0.2"/>
        </geometry>
        <origin xyz="0 0 0.2" rpy="0 0 0" />
        <material name="blue"/>
    </visual>
    </link>

    <link name="left_wheel_link">
    <visual>
        <geometry>
            <cylinder radius="0.2" length="0.05"/>
        </geometry>
        <origin xyz="0 0 0" rpy="1.57 0 0" />
        <material name="gray"/>
    </visual>
    </link>

    <joint name="base_left_wheel_joint" type="continuous">
        <parent link="base_link"/>
        <child link="left_wheel_link"/>
        <origin xyz="-0.1 0.225 0.2" rpy="0 0 0"/>
        <axis xyz="0 1 0"/>
    </joint>


    <link name="right_wheel_link">
    <visual>
        <geometry>
            <cylinder radius="0.2" length="0.05"/>
        </geometry>
        <origin xyz="0 0 0" rpy="1.57 0 0" />
        <material name="gray"/>
    </visual>
    </link>

    <joint name="base_right_wheel_joint" type="continuous">
        <parent link="base_link"/>
        <child link="right_wheel_link"/>
        <origin xyz="-0.1 -0.225 0.2" rpy="0 0 0"/>
        <axis xyz="0 1 0"/>
    </joint>

    


    <link name="support_wheel_link">
    <visual>
        <geometry>
            <sphere radius="0.05"/>
        </geometry>
        <origin xyz="0 0 0" rpy="0 0 0" />
        <material name="gray"/>
    </visual>
    </link>

    <joint name="base_support_wheel_joint" type="fixed">
        <parent link="base_link"/>
        <child link="support_wheel_link"/>
        <origin xyz="0.2 0 0.05" rpy="0 0 0"/>
    </joint>

</robot>
