<?xml version="1.0"?>
<robot name="robot_car">

    <material name="blue">
        <color rgba="0 0 1 1"/>
    </material>

    <material name="gray">
        <color rgba="0.5 0.5 0.5 1"/>
    </material>



    <link name="base_link">
    <visual>
        <geometry>
            <box size="0.6 0.4 0.2"/>
        </geometry>
        <origin xyz="0 0 0.2" rpy="0 0 0" />
        <material name="blue"/>
    </visual>
    </link>

    <link name="left_wheel">
    <visual>
        <geometry>
            <cylinder radius="0.2" length="0.05"/>
        </geometry>
        <origin xyz="0 0 0" rpy="0 0 0" />
        <material name="gray"/>
    </visual>
    </link>

    <joint name="base_left_wheel_joint" type="continuous">
        <parent link="base_link"/>
        <child link="right_wheel"/>
        <origin xyz="-0.1 0.225 0.2" rpy="-1.57 0 0"/>
        <axis xyz="0 0 1"/>
    </joint>

    <!-- <link name="camera_link">
    <visual>
        <geometry>
            <sphere radius="0.1"/>
        </geometry>
        <origin xyz="0 0 0" rpy="0 0 0" />
        <material name="red"/>
    </visual>
    </link>

    <joint name="shoulder_camera_joint" type="fixed">
        <parent link="shoulder_link"/>
        <child link="camera_link"/>
        <origin xyz="0 0 0.4" rpy="0 0 0"/>
    </joint> -->

</robot>
